2022-07-25 22:33:57,122 - ERROR - app.py - log_exception - 1449 - Exception on /d [GET]
Traceback (most recent call last):
  File "/home/lighthouse/.local/lib/python3.8/site-packages/flask/app.py", line 2073, in wsgi_app
    response = self.full_dispatch_request()
  File "/home/lighthouse/.local/lib/python3.8/site-packages/flask/app.py", line 1519, in full_dispatch_request
    rv = self.handle_user_exception(e)
  File "/home/lighthouse/.local/lib/python3.8/site-packages/flask/app.py", line 1517, in full_dispatch_request
    rv = self.dispatch_request()
  File "/home/lighthouse/.local/lib/python3.8/site-packages/flask/app.py", line 1503, in dispatch_request
    return self.ensure_sync(self.view_functions[rule.endpoint])(**req.view_args)
  File "/var/www/xxq/server.py", line 113, in down
    f=open('./download/data.csv','wb')
FileNotFoundError: [Errno 2] No such file or directory: './download/data.csv'
2022-07-25 22:36:30,622 - ERROR - app.py - log_exception - 1449 - Exception on /d [GET]
Traceback (most recent call last):
  File "/usr/local/lib/python3.8/dist-packages/flask/app.py", line 2073, in wsgi_app
    response = self.full_dispatch_request()
  File "/usr/local/lib/python3.8/dist-packages/flask/app.py", line 1519, in full_dispatch_request
    rv = self.handle_user_exception(e)
  File "/usr/local/lib/python3.8/dist-packages/flask/app.py", line 1517, in full_dispatch_request
    rv = self.dispatch_request()
  File "/usr/local/lib/python3.8/dist-packages/flask/app.py", line 1503, in dispatch_request
    return self.ensure_sync(self.view_functions[rule.endpoint])(**req.view_args)
  File "../server.py", line 113, in down
    f=open('./down/data.csv','wb')
FileNotFoundError: [Errno 2] No such file or directory: './down/data.csv'
